<mujoco model="hook_scenario">
  <compiler angle="radian" meshdir=""/>
  <option timestep="0.001"/>
  <visual>
    <quality shadowsize="0"/>
  </visual>

  <asset>
    <mesh file="../assets/quad_model.stl" name="drone" smoothnormal="true" scale=".01 .01 .01"/>
    <mesh file="hook.stl" name="hook" smoothnormal="true" scale=".005 .005 .005"/>
    <texture type="skybox" builtin="gradient" rgb1=".3 .5 .7" rgb2="0 0 0" width="512" height="512"/>
    <texture name="grid" type="2d" builtin="checker" width="512" height="512" rgb1=".1 .2 .3" rgb2=".2 .3 .4"/>
    <material name="grid" texture="grid" texrepeat="1 1" texuniform="true" reflectance=".0"/>
  </asset>

  <worldbody>
    <camera pos="2.867 -5.173 1.776" xyaxes="0.875 0.485 0.000 -0.139 0.252 0.958"/>
    <geom size="50 50 .05" type="plane" material="grid" condim="3"/>
    <light dir=".2 1 -.4" diffuse="1 1 1" specular="0.6 0.9 0.6" pos="-2 -10 6" cutoff="70"/>
    <light dir="-.2 1 -.4" diffuse="1 1 1" specular="0.6 0.9 0.6" pos="2 -10 6" cutoff="70"/>

    <body name="drone" pos="0 0 1.5">
        <inertial pos="0 0 0" diaginertia="1.5e-3 1.45e-3 2.66e-3" mass="0.605"/>
        <joint type="free"/>
        <geom name="drone" type="mesh" pos="0 0 0.05" euler="0 0 1.57" mesh="drone"/>
        <site name="drone_cog" pos="0 0 0"/>
        <body name="rod" pos="0 0 0" euler="0 0 0">
            <geom type="cylinder" fromto="0 0 0  0 0 -0.4" size="0.005" mass="0.00"/>
            <site name="rod_end" pos="0 0 -0.4" type="sphere" size="0.002"/>
            <joint axis="0 1 0" pos="0 0 0" damping="0.0001"/>
            <body name="hook0" pos="0 0 -0.4" euler="0 3.141592 0">
            <geom type="capsule" pos="0 0 0.02" size="0.005 0.02" mass="0.001"/>

            <geom type="capsule" pos="0 0.01299 0.04750" euler="-1.04720 0 0" size="0.005 0.01800" mass="0.0001"/>
            <geom type="capsule" pos="0 0.02598 0.07000" euler="0.00000 0 0" size="0.005 0.01800" mass="0.0001"/>
            <geom type="capsule" pos="0 0.01299 0.09250" euler="1.04720 0 0" size="0.005 0.01800" mass="0.0001"/>
            <geom type="capsule" pos="0 -0.01299 0.09250" euler="2.09440 0 0" size="0.005 0.01800" mass="0.0001"/>



                




            </body>
<!--            <body name="hook" pos="0 0 -0.55" euler="-1.57 1.57 3.141592">-->
<!--    &lt;!&ndash;        <inertial pos="0 0 0" diaginertia="1.4e-5 1.4e-5 2.17e-5" mass="0.028"/>&ndash;&gt;-->
<!--                <geom name="hook" type="mesh" pos="0 0 0" mesh="hook" mass="0.01"/>-->
<!--                <joint axis="0 1 0" pos="0 0.15 0" damping="0.002"/>-->
<!--                <site name="hook_top" pos="0 0.15 0" type="sphere" size="0.002"/>-->
<!--    </body>-->
    </body>
    </body>

    <body name="load1" pos="1 0 0.05">
        <geom type="box" size=".075 .075 .05" mass="0.06"/>
        <joint type="free"/>
        <body name="hook1" pos="0 0 .05" euler="0 0 -1.57">
            <geom type="capsule" pos="0 0 0.02" size="0.005 0.02" mass="0.0001"/>

            <geom type="capsule" pos="0 0.01173 0.04565" euler="-1.12200 0 0" size="0.005 0.01562" mass="0.0001"/>
            <geom type="capsule" pos="0 0.01061 0.04439" euler="-1.17810 0 0" size="0.005 0.01378" mass="0.0001"/>
            <geom type="capsule" pos="0 0.02561 0.05939" euler="-0.39270 0 0" size="0.005 0.01378" mass="0.0001"/>
            <geom type="capsule" pos="0 0.02561 0.08061" euler="0.39270 0 0" size="0.005 0.01378" mass="0.0001"/>
            <geom type="capsule" pos="0 0.01061 0.09561" euler="1.17810 0 0" size="0.005 0.01378" mass="0.0001"/>
            <geom type="capsule" pos="0 -0.01061 0.09561" euler="1.96350 0 0" size="0.005 0.01378" mass="0.0001"/>
            <geom type="capsule" pos="0 -0.02561 0.08061" euler="2.74889 0 0" size="0.005 0.01378" mass="0.0001"/>





        </body>
    </body>

  </worldbody>

  <actuator>
      <general site="drone_cog" gear=" 0 0 1 0 0 0" ctrllimited="true" ctrlrange="0 20"/>
      <general site="drone_cog" gear=" 0 0 0 1 0 0" ctrllimited="true" ctrlrange="-0.3 0.3"/>
      <general site="drone_cog" gear=" 0 0 0 0 1 0" ctrllimited="true" ctrlrange="-0.3 0.3"/>
      <general site="drone_cog" gear=" 0 0 0 0 0 1" ctrllimited="true" ctrlrange="-0.3 0.3"/>
  </actuator>
  <sensor>
      <gyro name="drone" site="drone_cog"/>
  </sensor>
</mujoco>